<?xml version="1.0" encoding="UTF-8"?>
<testng-results ignored="0" total="2" passed="0" failed="2" skipped="0">
  <reporter-output>
  </reporter-output>
  <suite started-at="2021-07-21T16:20:12 ICT" name="Default suite" finished-at="2021-07-21T16:20:16 ICT" duration-ms="4069">
    <groups>
    </groups>
    <test started-at="2021-07-21T16:20:12 ICT" name="Default test" finished-at="2021-07-21T16:20:16 ICT" duration-ms="4069">
      <class name="test.testCreate">
        <test-method is-config="true" signature="initDAO()[pri:0, instance:test.testCreate@7e5afaa6]" started-at="2021-07-21T16:20:12 ICT" name="initDAO" finished-at="2021-07-21T16:20:16 ICT" duration-ms="3848" status="PASS">
          <reporter-output>
          </reporter-output>
        </test-method> <!-- initDAO -->
        <test-method signature="insertproduct()[pri:0, instance:test.testCreate@7e5afaa6]" started-at="2021-07-21T16:20:16 ICT" name="insertproduct" finished-at="2021-07-21T16:20:16 ICT" duration-ms="115" status="FAIL">
          <exception class="javax.persistence.RollbackException">
            <message>
              <![CDATA[Error while committing the transaction]]>
            </message>
            <full-stacktrace>
              <![CDATA[javax.persistence.RollbackException: Error while committing the transaction
at org.hibernate.internal.ExceptionConverterImpl.convertCommitException(ExceptionConverterImpl.java:81)
at org.hibernate.engine.transaction.internal.TransactionImpl.commit(TransactionImpl.java:104)
at dao.ProductDAO.insert(ProductDAO.java:24)
at test.testCreate.insertproduct(testCreate.java:24)
at java.base/jdk.internal.reflect.NativeMethodAccessorImpl.invoke0(Native Method)
at java.base/jdk.internal.reflect.NativeMethodAccessorImpl.invoke(NativeMethodAccessorImpl.java:64)
at java.base/jdk.internal.reflect.DelegatingMethodAccessorImpl.invoke(DelegatingMethodAccessorImpl.java:43)
at java.base/java.lang.reflect.Method.invoke(Method.java:564)
at org.testng.internal.MethodInvocationHelper.invokeMethod(MethodInvocationHelper.java:133)
at org.testng.internal.TestInvoker.invokeMethod(TestInvoker.java:598)
at org.testng.internal.TestInvoker.invokeTestMethod(TestInvoker.java:173)
at org.testng.internal.MethodRunner.runInSequence(MethodRunner.java:46)
at org.testng.internal.TestInvoker$MethodInvocationAgent.invoke(TestInvoker.java:824)
at org.testng.internal.TestInvoker.invokeTestMethods(TestInvoker.java:146)
at org.testng.internal.TestMethodWorker.invokeTestMethods(TestMethodWorker.java:146)
at org.testng.internal.TestMethodWorker.run(TestMethodWorker.java:128)
at java.base/java.util.ArrayList.forEach(ArrayList.java:1511)
at org.testng.TestRunner.privateRun(TestRunner.java:794)
at org.testng.TestRunner.run(TestRunner.java:596)
at org.testng.SuiteRunner.runTest(SuiteRunner.java:377)
at org.testng.SuiteRunner.runSequentially(SuiteRunner.java:371)
at org.testng.SuiteRunner.privateRun(SuiteRunner.java:332)
at org.testng.SuiteRunner.run(SuiteRunner.java:276)
at org.testng.SuiteRunnerWorker.runSuite(SuiteRunnerWorker.java:53)
at org.testng.SuiteRunnerWorker.run(SuiteRunnerWorker.java:96)
at org.testng.TestNG.runSuitesSequentially(TestNG.java:1212)
at org.testng.TestNG.runSuitesLocally(TestNG.java:1134)
at org.testng.TestNG.runSuites(TestNG.java:1063)
at org.testng.TestNG.run(TestNG.java:1031)
at org.testng.remote.AbstractRemoteTestNG.run(AbstractRemoteTestNG.java:115)
at org.testng.remote.RemoteTestNG.initAndRun(RemoteTestNG.java:251)
at org.testng.remote.RemoteTestNG.main(RemoteTestNG.java:77)
Caused by: javax.persistence.PersistenceException: org.hibernate.exception.ConstraintViolationException: could not execute statement
at org.hibernate.internal.ExceptionConverterImpl.convert(ExceptionConverterImpl.java:154)
at org.hibernate.internal.ExceptionConverterImpl.convert(ExceptionConverterImpl.java:181)
at org.hibernate.internal.ExceptionConverterImpl.convertCommitException(ExceptionConverterImpl.java:65)
... 31 more
Caused by: org.hibernate.exception.ConstraintViolationException: could not execute statement
at org.hibernate.exception.internal.SQLStateConversionDelegate.convert(SQLStateConversionDelegate.java:109)
at org.hibernate.exception.internal.StandardSQLExceptionConverter.convert(StandardSQLExceptionConverter.java:42)
at org.hibernate.engine.jdbc.spi.SqlExceptionHelper.convert(SqlExceptionHelper.java:113)
at org.hibernate.engine.jdbc.spi.SqlExceptionHelper.convert(SqlExceptionHelper.java:99)
at org.hibernate.engine.jdbc.internal.ResultSetReturnImpl.executeUpdate(ResultSetReturnImpl.java:200)
at org.hibernate.persister.entity.AbstractEntityPersister.insert(AbstractEntityPersister.java:3298)
at org.hibernate.persister.entity.AbstractEntityPersister.insert(AbstractEntityPersister.java:3825)
at org.hibernate.action.internal.EntityInsertAction.execute(EntityInsertAction.java:107)
at org.hibernate.engine.spi.ActionQueue.executeActions(ActionQueue.java:604)
at org.hibernate.engine.spi.ActionQueue.lambda$executeActions$1(ActionQueue.java:478)
at java.base/java.util.LinkedHashMap.forEach(LinkedHashMap.java:723)
at org.hibernate.engine.spi.ActionQueue.executeActions(ActionQueue.java:475)
at org.hibernate.event.internal.AbstractFlushingEventListener.performExecutions(AbstractFlushingEventListener.java:344)
at org.hibernate.event.internal.DefaultFlushEventListener.onFlush(DefaultFlushEventListener.java:40)
at org.hibernate.event.service.internal.EventListenerGroupImpl.fireEventOnEachListener(EventListenerGroupImpl.java:99)
at org.hibernate.internal.SessionImpl.doFlush(SessionImpl.java:1362)
at org.hibernate.internal.SessionImpl.managedFlush(SessionImpl.java:453)
at org.hibernate.internal.SessionImpl.flushBeforeTransactionCompletion(SessionImpl.java:3212)
at org.hibernate.internal.SessionImpl.beforeTransactionCompletion(SessionImpl.java:2380)
at org.hibernate.engine.jdbc.internal.JdbcCoordinatorImpl.beforeTransactionCompletion(JdbcCoordinatorImpl.java:448)
at org.hibernate.resource.transaction.backend.jdbc.internal.JdbcResourceLocalTransactionCoordinatorImpl.beforeCompletionCallback(JdbcResourceLocalTransactionCoordinatorImpl.java:183)
at org.hibernate.resource.transaction.backend.jdbc.internal.JdbcResourceLocalTransactionCoordinatorImpl.access$300(JdbcResourceLocalTransactionCoordinatorImpl.java:40)
at org.hibernate.resource.transaction.backend.jdbc.internal.JdbcResourceLocalTransactionCoordinatorImpl$TransactionDriverControlImpl.commit(JdbcResourceLocalTransactionCoordinatorImpl.java:281)
at org.hibernate.engine.transaction.internal.TransactionImpl.commit(TransactionImpl.java:101)
... 30 more
Caused by: com.microsoft.sqlserver.jdbc.SQLServerException: Violation of PRIMARY KEY constraint 'PK__sanpham__7A217672EC469A12'. Cannot insert duplicate key in object 'dbo.sanpham'. The duplicate key value is (SP60).
at com.microsoft.sqlserver.jdbc.SQLServerException.makeFromDatabaseError(SQLServerException.java:262)
at com.microsoft.sqlserver.jdbc.SQLServerStatement.getNextResult(SQLServerStatement.java:1632)
at com.microsoft.sqlserver.jdbc.SQLServerPreparedStatement.doExecutePreparedStatement(SQLServerPreparedStatement.java:602)
at com.microsoft.sqlserver.jdbc.SQLServerPreparedStatement$PrepStmtExecCmd.doExecute(SQLServerPreparedStatement.java:524)
at com.microsoft.sqlserver.jdbc.TDSCommand.execute(IOBuffer.java:7418)
at com.microsoft.sqlserver.jdbc.SQLServerConnection.executeCommand(SQLServerConnection.java:3272)
at com.microsoft.sqlserver.jdbc.SQLServerStatement.executeCommand(SQLServerStatement.java:247)
at com.microsoft.sqlserver.jdbc.SQLServerStatement.executeStatement(SQLServerStatement.java:222)
at com.microsoft.sqlserver.jdbc.SQLServerPreparedStatement.executeUpdate(SQLServerPreparedStatement.java:473)
at org.hibernate.engine.jdbc.internal.ResultSetReturnImpl.executeUpdate(ResultSetReturnImpl.java:197)
... 49 more
]]>
            </full-stacktrace>
          </exception> <!-- javax.persistence.RollbackException -->
          <reporter-output>
          </reporter-output>
        </test-method> <!-- insertproduct -->
        <test-method signature="updateProduct()[pri:0, instance:test.testCreate@7e5afaa6]" started-at="2021-07-21T16:20:16 ICT" name="updateProduct" finished-at="2021-07-21T16:20:16 ICT" duration-ms="54" status="FAIL">
          <exception class="java.lang.AssertionError">
            <message>
              <![CDATA[expected [false] but found [true]]]>
            </message>
            <full-stacktrace>
              <![CDATA[java.lang.AssertionError: expected [false] but found [true]
at org.testng.Assert.fail(Assert.java:99)
at org.testng.Assert.failNotEquals(Assert.java:1037)
at org.testng.Assert.assertEqualsImpl(Assert.java:140)
at org.testng.Assert.assertEquals(Assert.java:122)
at org.testng.Assert.assertEquals(Assert.java:819)
at org.testng.Assert.assertEquals(Assert.java:829)
at test.testCreate.updateProduct(testCreate.java:31)
at java.base/jdk.internal.reflect.NativeMethodAccessorImpl.invoke0(Native Method)
at java.base/jdk.internal.reflect.NativeMethodAccessorImpl.invoke(NativeMethodAccessorImpl.java:64)
at java.base/jdk.internal.reflect.DelegatingMethodAccessorImpl.invoke(DelegatingMethodAccessorImpl.java:43)
at java.base/java.lang.reflect.Method.invoke(Method.java:564)
at org.testng.internal.MethodInvocationHelper.invokeMethod(MethodInvocationHelper.java:133)
at org.testng.internal.TestInvoker.invokeMethod(TestInvoker.java:598)
at org.testng.internal.TestInvoker.invokeTestMethod(TestInvoker.java:173)
at org.testng.internal.MethodRunner.runInSequence(MethodRunner.java:46)
at org.testng.internal.TestInvoker$MethodInvocationAgent.invoke(TestInvoker.java:824)
at org.testng.internal.TestInvoker.invokeTestMethods(TestInvoker.java:146)
at org.testng.internal.TestMethodWorker.invokeTestMethods(TestMethodWorker.java:146)
at org.testng.internal.TestMethodWorker.run(TestMethodWorker.java:128)
at java.base/java.util.ArrayList.forEach(ArrayList.java:1511)
at org.testng.TestRunner.privateRun(TestRunner.java:794)
at org.testng.TestRunner.run(TestRunner.java:596)
at org.testng.SuiteRunner.runTest(SuiteRunner.java:377)
at org.testng.SuiteRunner.runSequentially(SuiteRunner.java:371)
at org.testng.SuiteRunner.privateRun(SuiteRunner.java:332)
at org.testng.SuiteRunner.run(SuiteRunner.java:276)
at org.testng.SuiteRunnerWorker.runSuite(SuiteRunnerWorker.java:53)
at org.testng.SuiteRunnerWorker.run(SuiteRunnerWorker.java:96)
at org.testng.TestNG.runSuitesSequentially(TestNG.java:1212)
at org.testng.TestNG.runSuitesLocally(TestNG.java:1134)
at org.testng.TestNG.runSuites(TestNG.java:1063)
at org.testng.TestNG.run(TestNG.java:1031)
at org.testng.remote.AbstractRemoteTestNG.run(AbstractRemoteTestNG.java:115)
at org.testng.remote.RemoteTestNG.initAndRun(RemoteTestNG.java:251)
at org.testng.remote.RemoteTestNG.main(RemoteTestNG.java:77)
]]>
            </full-stacktrace>
          </exception> <!-- java.lang.AssertionError -->
          <reporter-output>
          </reporter-output>
        </test-method> <!-- updateProduct -->
      </class> <!-- test.testCreate -->
    </test> <!-- Default test -->
  </suite> <!-- Default suite -->
</testng-results>
